Workbook

Sheet Generacion DD
B2: Generación de Números Pseudoaleatorios para DEMANDA
B6: se generaron 100 numero pseudoaleatorios semilla: 2026 multiplicador: 5324
F9: a= | G9: 5324
F10: X0 = | G10: 2026 | I10: Numero pseudoaleatorios | K10: Valores simulados
B11: 0 | C11: Y0 = (X0)*a = | D11: =G10*G9 | F11: X1 = | G11: =MID(TEXT(D11, "00000000"), 3, 4) | I11: R1 = | J11: =G11/10000 | K11: =IF(J11<=0.1287,0,IF(J11<=0.3926,1,IF(J11<=0.6631,2,IF(J11<=0.848,3,IF(J11<=0.9427,4,IF(J11<=0.9816,5,IF(J11<=0.9948,6,IF(J11<=0.9987,7,8)))))))) | L11: Primeros 20 numeros pseudoaleatorios DD
B12: 1 | C12: Y1 = (X1)*a = | D12: =G11*G9 | F12: X2 = | G12: =MID(TEXT(D12, "00000000"), 3, 4) | I12: R2 = | J12: =G12/10000 | K12: =IF(J12<=0.1287,0,IF(J12<=0.3926,1,IF(J12<=0.6631,2,IF(J12<=0.848,3,IF(J12<=0.9427,4,IF(J12<=0.9816,5,IF(J12<=0.9948,6,IF(J12<=0.9987,7,8)))))))) | L12: =J11 | M12: =J21
B13: 2 | C13: Y2 = (X2)*a = | D13: =G12*G9 | F13: X3 = | G13: =MID(TEXT(D13, "00000000"), 3, 4) | I13: R3 = | J13: =G13/10000 | K13: =IF(J13<=0.1287,0,IF(J13<=0.3926,1,IF(J13<=0.6631,2,IF(J13<=0.848,3,IF(J13<=0.9427,4,IF(J13<=0.9816,5,IF(J13<=0.9948,6,IF(J13<=0.9987,7,8)))))))) | L13: =J12 | M13: =J22
B14: 3 | C14: ="Y"&B14&" = (X"&B14&")*a =" | D14: =G13*$G$9 | F14: ="X"&B14+1&" =" | G14: =MID(TEXT(D14, "00000000"), 3, 4) | I14: ="R"&B14+1&" =" | J14: =G14/10000 | K14: =IF(J14<=0.1287,0,IF(J14<=0.3926,1,IF(J14<=0.6631,2,IF(J14<=0.848,3,IF(J14<=0.9427,4,IF(J14<=0.9816,5,IF(J14<=0.9948,6,IF(J14<=0.9987,7,8)))))))) | L14: =J13 | M14: =J23
B15: 4 | C15: ="Y"&B15&" = (X"&B15&")*a =" | D15: =G14*$G$9 | F15: ="X"&B15+1&" =" | G15: =MID(TEXT(D15, "00000000"), 3, 4) | I15: ="R"&B15+1&" =" | J15: =G15/10000 | K15: =IF(J15<=0.1287,0,IF(J15<=0.3926,1,IF(J15<=0.6631,2,IF(J15<=0.848,3,IF(J15<=0.9427,4,IF(J15<=0.9816,5,IF(J15<=0.9948,6,IF(J15<=0.9987,7,8)))))))) | L15: =J14 | M15: =J24
B16: 5 | C16: ="Y"&B16&" = (X"&B16&")*a =" | D16: =G15*$G$9 | F16: ="X"&B16+1&" =" | G16: =MID(TEXT(D16, "00000000"), 3, 4) | I16: ="R"&B16+1&" =" | J16: =G16/10000 | K16: =IF(J16<=0.1287,0,IF(J16<=0.3926,1,IF(J16<=0.6631,2,IF(J16<=0.848,3,IF(J16<=0.9427,4,IF(J16<=0.9816,5,IF(J16<=0.9948,6,IF(J16<=0.9987,7,8)))))))) | L16: =J15 | M16: =J25
B17: 6 | C17: ="Y"&B17&" = (X"&B17&")*a =" | D17: =G16*$G$9 | F17: ="X"&B17+1&" =" | G17: =MID(TEXT(D17, "00000000"), 3, 4) | I17: ="R"&B17+1&" =" | J17: =G17/10000 | K17: =IF(J17<=0.1287,0,IF(J17<=0.3926,1,IF(J17<=0.6631,2,IF(J17<=0.848,3,IF(J17<=0.9427,4,IF(J17<=0.9816,5,IF(J17<=0.9948,6,IF(J17<=0.9987,7,8)))))))) | L17: =J16 | M17: =J26
B18: 7 | C18: ="Y"&B18&" = (X"&B18&")*a =" | D18: =G17*$G$9 | F18: ="X"&B18+1&" =" | G18: =MID(TEXT(D18, "00000000"), 3, 4) | I18: ="R"&B18+1&" =" | J18: =G18/10000 | K18: =IF(J18<=0.1287,0,IF(J18<=0.3926,1,IF(J18<=0.6631,2,IF(J18<=0.848,3,IF(J18<=0.9427,4,IF(J18<=0.9816,5,IF(J18<=0.9948,6,IF(J18<=0.9987,7,8)))))))) | L18: =J17 | M18: =J27
B19: 8 | C19: ="Y"&B19&" = (X"&B19&")*a =" | D19: =G18*$G$9 | F19: ="X"&B19+1&" =" | G19: =MID(TEXT(D19, "00000000"), 3, 4) | I19: ="R"&B19+1&" =" | J19: =G19/10000 | K19: =IF(J19<=0.1287,0,IF(J19<=0.3926,1,IF(J19<=0.6631,2,IF(J19<=0.848,3,IF(J19<=0.9427,4,IF(J19<=0.9816,5,IF(J19<=0.9948,6,IF(J19<=0.9987,7,8)))))))) | L19: =J18 | M19: =J28
B20: 9 | C20: ="Y"&B20&" = (X"&B20&")*a =" | D20: =G19*$G$9 | F20: ="X"&B20+1&" =" | G20: =MID(TEXT(D20, "00000000"), 3, 4) | I20: ="R"&B20+1&" =" | J20: =G20/10000 | K20: =IF(J20<=0.1287,0,IF(J20<=0.3926,1,IF(J20<=0.6631,2,IF(J20<=0.848,3,IF(J20<=0.9427,4,IF(J20<=0.9816,5,IF(J20<=0.9948,6,IF(J20<=0.9987,7,8)))))))) | L20: =J19 | M20: =J29
B21: 10 | C21: ="Y"&B21&" = (X"&B21&")*a =" | D21: =G20*$G$9 | F21: ="X"&B21+1&" =" | G21: =MID(TEXT(D21, "00000000"), 3, 4) | I21: ="R"&B21+1&" =" | J21: =G21/10000 | K21: =IF(J21<=0.1287,0,IF(J21<=0.3926,1,IF(J21<=0.6631,2,IF(J21<=0.848,3,IF(J21<=0.9427,4,IF(J21<=0.9816,5,IF(J21<=0.9948,6,IF(J21<=0.9987,7,8)))))))) | L21: =J20 | M21: =J30
B22: 11 | C22: ="Y"&B22&" = (X"&B22&")*a =" | D22: =G21*$G$9 | F22: ="X"&B22+1&" =" | G22: =MID(TEXT(D22, "00000000"), 3, 4) | I22: ="R"&B22+1&" =" | J22: =G22/10000 | K22: =IF(J22<=0.1287,0,IF(J22<=0.3926,1,IF(J22<=0.6631,2,IF(J22<=0.848,3,IF(J22<=0.9427,4,IF(J22<=0.9816,5,IF(J22<=0.9948,6,IF(J22<=0.9987,7,8)))))))) | L22: A partir de aca verificamos los numeros, que sean realmente pseudo aleatorio
B23: 12 | C23: ="Y"&B23&" = (X"&B23&")*a =" | D23: =G22*$G$9 | F23: ="X"&B23+1&" =" | G23: =MID(TEXT(D23, "00000000"), 3, 4) | I23: ="R"&B23+1&" =" | J23: =G23/10000 | K23: =IF(J23<=0.1287,0,IF(J23<=0.3926,1,IF(J23<=0.6631,2,IF(J23<=0.848,3,IF(J23<=0.9427,4,IF(J23<=0.9816,5,IF(J23<=0.9948,6,IF(J23<=0.9987,7,8)))))))) | L23: 1ero: Prueba de medias
B24: 13 | C24: ="Y"&B24&" = (X"&B24&")*a =" | D24: =G23*$G$9 | F24: ="X"&B24+1&" =" | G24: =MID(TEXT(D24, "00000000"), 3, 4) | I24: ="R"&B24+1&" =" | J24: =G24/10000 | K24: =IF(J24<=0.1287,0,IF(J24<=0.3926,1,IF(J24<=0.6631,2,IF(J24<=0.848,3,IF(J24<=0.9427,4,IF(J24<=0.9816,5,IF(J24<=0.9948,6,IF(J24<=0.9987,7,8)))))))) | L24: 2do Prueba de varianza
B25: 14 | C25: ="Y"&B25&" = (X"&B25&")*a =" | D25: =G24*$G$9 | F25: ="X"&B25+1&" =" | G25: =MID(TEXT(D25, "00000000"), 3, 4) | I25: ="R"&B25+1&" =" | J25: =G25/10000 | K25: =IF(J25<=0.1287,0,IF(J25<=0.3926,1,IF(J25<=0.6631,2,IF(J25<=0.848,3,IF(J25<=0.9427,4,IF(J25<=0.9816,5,IF(J25<=0.9948,6,IF(J25<=0.9987,7,8)))))))) | L25: 3ero Prueba de Chi-Cuadrada
B26: 15 | C26: ="Y"&B26&" = (X"&B26&")*a =" | D26: =G25*$G$9 | F26: ="X"&B26+1&" =" | G26: =MID(TEXT(D26, "00000000"), 3, 4) | I26: ="R"&B26+1&" =" | J26: =G26/10000 | K26: =IF(J26<=0.1287,0,IF(J26<=0.3926,1,IF(J26<=0.6631,2,IF(J26<=0.848,3,IF(J26<=0.9427,4,IF(J26<=0.9816,5,IF(J26<=0.9948,6,IF(J26<=0.9987,7,8)))))))) | L26: 4to Prueba Corridas Arriba y Abajo
B27: 16 | C27: ="Y"&B27&" = (X"&B27&")*a =" | D27: =G26*$G$9 | F27: ="X"&B27+1&" =" | G27: =MID(TEXT(D27, "00000000"), 3, 4) | I27: ="R"&B27+1&" =" | J27: =G27/10000 | K27: =IF(J27<=0.1287,0,IF(J27<=0.3926,1,IF(J27<=0.6631,2,IF(J27<=0.848,3,IF(J27<=0.9427,4,IF(J27<=0.9816,5,IF(J27<=0.9948,6,IF(J27<=0.9987,7,8))))))))
B28: 17 | C28: ="Y"&B28&" = (X"&B28&")*a =" | D28: =G27*$G$9 | F28: ="X"&B28+1&" =" | G28: =MID(TEXT(D28, "00000000"), 3, 4) | I28: ="R"&B28+1&" =" | J28: =G28/10000 | K28: =IF(J28<=0.1287,0,IF(J28<=0.3926,1,IF(J28<=0.6631,2,IF(J28<=0.848,3,IF(J28<=0.9427,4,IF(J28<=0.9816,5,IF(J28<=0.9948,6,IF(J28<=0.9987,7,8))))))))
B29: 18 | C29: ="Y"&B29&" = (X"&B29&")*a =" | D29: =G28*$G$9 | F29: ="X"&B29+1&" =" | G29: =MID(TEXT(D29, "00000000"), 3, 4) | I29: ="R"&B29+1&" =" | J29: =G29/10000 | K29: =IF(J29<=0.1287,0,IF(J29<=0.3926,1,IF(J29<=0.6631,2,IF(J29<=0.848,3,IF(J29<=0.9427,4,IF(J29<=0.9816,5,IF(J29<=0.9948,6,IF(J29<=0.9987,7,8))))))))
B30: 19 | C30: ="Y"&B30&" = (X"&B30&")*a =" | D30: =G29*$G$9 | F30: ="X"&B30+1&" =" | G30: =MID(TEXT(D30, "00000000"), 3, 4) | I30: ="R"&B30+1&" =" | J30: =G30/10000 | K30: =IF(J30<=0.1287,0,IF(J30<=0.3926,1,IF(J30<=0.6631,2,IF(J30<=0.848,3,IF(J30<=0.9427,4,IF(J30<=0.9816,5,IF(J30<=0.9948,6,IF(J30<=0.9987,7,8))))))))
B31: 20 | C31: ="Y"&B31&" = (X"&B31&")*a =" | D31: =G30*$G$9 | F31: ="X"&B31+1&" =" | G31: =MID(TEXT(D31, "00000000"), 3, 4) | I31: ="R"&B31+1&" =" | J31: =G31/10000 | K31: =IF(J31<=0.1287,0,IF(J31<=0.3926,1,IF(J31<=0.6631,2,IF(J31<=0.848,3,IF(J31<=0.9427,4,IF(J31<=0.9816,5,IF(J31<=0.9948,6,IF(J31<=0.9987,7,8))))))))
B32: 21 | C32: ="Y"&B32&" = (X"&B32&")*a =" | D32: =G31*$G$9 | F32: ="X"&B32+1&" =" | G32: =MID(TEXT(D32, "00000000"), 3, 4) | I32: ="R"&B32+1&" =" | J32: =G32/10000 | K32: =IF(J32<=0.1287,0,IF(J32<=0.3926,1,IF(J32<=0.6631,2,IF(J32<=0.848,3,IF(J32<=0.9427,4,IF(J32<=0.9816,5,IF(J32<=0.9948,6,IF(J32<=0.9987,7,8))))))))
B33: 22 | C33: ="Y"&B33&" = (X"&B33&")*a =" | D33: =G32*$G$9 | F33: ="X"&B33+1&" =" | G33: =MID(TEXT(D33, "00000000"), 3, 4) | I33: ="R"&B33+1&" =" | J33: =G33/10000 | K33: =IF(J33<=0.1287,0,IF(J33<=0.3926,1,IF(J33<=0.6631,2,IF(J33<=0.848,3,IF(J33<=0.9427,4,IF(J33<=0.9816,5,IF(J33<=0.9948,6,IF(J33<=0.9987,7,8))))))))
B34: 23 | C34: ="Y"&B34&" = (X"&B34&")*a =" | D34: =G33*$G$9 | F34: ="X"&B34+1&" =" | G34: =MID(TEXT(D34, "00000000"), 3, 4) | I34: ="R"&B34+1&" =" | J34: =G34/10000 | K34: =IF(J34<=0.1287,0,IF(J34<=0.3926,1,IF(J34<=0.6631,2,IF(J34<=0.848,3,IF(J34<=0.9427,4,IF(J34<=0.9816,5,IF(J34<=0.9948,6,IF(J34<=0.9987,7,8))))))))
B35: 24 | C35: ="Y"&B35&" = (X"&B35&")*a =" | D35: =G34*$G$9 | F35: ="X"&B35+1&" =" | G35: =MID(TEXT(D35, "00000000"), 3, 4) | I35: ="R"&B35+1&" =" | J35: =G35/10000 | K35: =IF(J35<=0.1287,0,IF(J35<=0.3926,1,IF(J35<=0.6631,2,IF(J35<=0.848,3,IF(J35<=0.9427,4,IF(J35<=0.9816,5,IF(J35<=0.9948,6,IF(J35<=0.9987,7,8))))))))
B36: 25 | C36: ="Y"&B36&" = (X"&B36&")*a =" | D36: =G35*$G$9 | F36: ="X"&B36+1&" =" | G36: =MID(TEXT(D36, "00000000"), 3, 4) | I36: ="R"&B36+1&" =" | J36: =G36/10000 | K36: =IF(J36<=0.1287,0,IF(J36<=0.3926,1,IF(J36<=0.6631,2,IF(J36<=0.848,3,IF(J36<=0.9427,4,IF(J36<=0.9816,5,IF(J36<=0.9948,6,IF(J36<=0.9987,7,8))))))))
B37: 26 | C37: ="Y"&B37&" = (X"&B37&")*a =" | D37: =G36*$G$9 | F37: ="X"&B37+1&" =" | G37: =MID(TEXT(D37, "00000000"), 3, 4) | I37: ="R"&B37+1&" =" | J37: =G37/10000 | K37: =IF(J37<=0.1287,0,IF(J37<=0.3926,1,IF(J37<=0.6631,2,IF(J37<=0.848,3,IF(J37<=0.9427,4,IF(J37<=0.9816,5,IF(J37<=0.9948,6,IF(J37<=0.9987,7,8))))))))
B38: 27 | C38: ="Y"&B38&" = (X"&B38&")*a =" | D38: =G37*$G$9 | F38: ="X"&B38+1&" =" | G38: =MID(TEXT(D38, "00000000"), 3, 4) | I38: ="R"&B38+1&" =" | J38: =G38/10000 | K38: =IF(J38<=0.1287,0,IF(J38<=0.3926,1,IF(J38<=0.6631,2,IF(J38<=0.848,3,IF(J38<=0.9427,4,IF(J38<=0.9816,5,IF(J38<=0.9948,6,IF(J38<=0.9987,7,8))))))))
... B10010: 9999 | C10010: ="Y"&B10010&" = (X"&B10010&")*a =" | D10010: =G10009*$G$9 | F10010: ="X"&B10010+1&" =" | G10010: =MID(TEXT(D10010, "00000000"), 3, 4) | I10010: ="R"&B10010+1&" =" | J10010: =G10010/10000 | K10010: =IF(J10010<=0.1287,0,IF(J10010<=0.3926,1,IF(J10010<=0.6631,2,IF(J10010<=0.848,3,IF(J10010<=0.9427,4,IF(J10010<=0.9816,5,IF(J10010<=0.9948,6,IF(J10010<=0.9987,7,8))))))))

Sheet Prueba de Medias
I2: Nivel de Significación
B3: 0.7864 | C3: Tamaño de Muestra | D3: n = | E3: =COUNT(B3:B10002) | I3: a = | J3: 0.05 | K3: 0.05 | M3: nivel de aceptación = 95% | O3: =1-K3
B4: 0.8679 | C4: Media | D4: r = | E4: =(SUM(B3:B10002))/$E$3 | F4: =AVERAGE(B3:B10002) | I4: a/2 = | J4: =K3/2
B5: 0.2069 | C5: Z Critico | D5: Z a/2 = | E5: =ROUND(F5,3) | F5: =NORMSINV(J5) | I5: 1-(a/2) = | J5: =1-J4 | L5: Busco 0,975 en el cuerpo de la tabla de distribución Normal estándar.
B6: 0.0153
B7: 0.8145 | D7: LI r prom= | E7: =(1/2)-(E5*(1/(SQRT(12*E3))))
B8: 0.3639
B9: 0.374 | D9: LS r prom= | E9: =(1/2)+(E5*(1/(SQRT(12*E3))))
B10: 0.9117
B11: 0.5389 | G11: Limites de Aceptación
B12: 0.691 | H12: 0.44341967 | I12: ≤ | J12: =ROUND(E4,3) | K12: ≤ | L12: 0.55658033
B13: 0.7888
B14: 0.9957 | D14: Como el valor del promedio 0,549 se encuentra entre los límites de aceptación, se concluye que no se puede rechazar que el conjunto de 100 números ri tiene un valor esperado de 0,5 con un nivel de aceptación de 95 %.
B15: 0.011
B16: 0.5856
B17: 0.1773
B18: 0.4394
B19: 0.3936
B20: 0.9552
B21: 0.8548
B22: 0.5095
B23: 0.1257
B24: 0.6922
B25: 0.8527
B26: 0.3977
... B102: 0.1397
B103: ='Generacion DD'!J111
B104: ='Generacion DD'!J112
B105: ='Generacion DD'!J113
B106: ='Generacion DD'!J114
B107: ='Generacion DD'!J115
B108: ='Generacion DD'!J116
B109: ='Generacion DD'!J117
B110: ='Generacion DD'!J118
B111: ='Generacion DD'!J119
B112: ='Generacion DD'!J120
B113: ='Generacion DD'!J121
B114: ='Generacion DD'!J122
... B10002: ='Generacion DD'!J10010

Sheet Prueba de Varianza
A1: Prueba de Varianza
B2: ri | C2: ri-r prom | D2: (ri-r prom)2
B3: 0.7864 | C3: =B3-$G$4 | D3: =POWER(C3,2) | F3: n = | G3: =COUNT(B3:B10002) | I3: nivel de aceptación = 95%
B4: 0.8679 | C4: =B4-$G$4 | D4: =POWER(C4,2) | F4: r = | G4: 0.549
B5: 0.2069 | C5: =B5-$G$4 | D5: =POWER(C5,2)
B6: 0.0153 | C6: =B6-$G$4 | D6: =POWER(C6,2)
B7: 0.8145 | C7: =B7-$G$4 | D7: =POWER(C7,2)
B8: 0.3639 | C8: =B8-$G$4 | D8: =POWER(C8,2) | F8: V(r) = | G8: =D10003/($G$3-1) | H8: =_xlfn.VAR.S(B3:B10002) | J8: n - 1 = | K8: =G3-1 | N8: a/2 = | O8: =L9/2
B9: 0.374 | C9: =B9-$G$4 | D9: =POWER(C9,2) | F9: 1-(a/2) = | G9: =1-G8 | J9: a = | K9: 0.05 | L9: 0.05 | N9: 1-(a/2) = | O9: =1-O8
B10: 0.9117 | C10: =B10-$G$4 | D10: =POWER(C10,2) | F10: X2 (0,975;9) = | G10: =ROUND(H10,2) | H10: =_xlfn.CHISQ.INV.RT(O9,K8) | J10: Busco en la Tabla X2 la Fila 9 y la Columna 0,975, y escribo el valor que se encuentra en la intersección de ambos valores.
B11: 0.5389 | C11: =B11-$G$4 | D11: =POWER(C11,2) | F11: X2 (0,025;9) = | G11: =ROUND(H11,2) | H11: =_xlfn.CHISQ.INV.RT(O8,K8) | J11: Busco en la Tabla X2 la Fila 9 y la Columna 0,025, y escribo el valor que se encuentra en la intersección de ambos valores.
B12: 0.691 | C12: =B12-$G$4 | D12: =POWER(C12,2)
B13: 0.7888 | C13: =B13-$G$4 | D13: =POWER(C13,2) | F13: LI V(r) = | G13: =G10/(12*($G$3-1))
B14: 0.9957 | C14: =B14-$G$4 | D14: =POWER(C14,2) | F14: LS V(r) = | G14: =G11/(12*($G$3-1))
B15: 0.011 | C15: =B15-$G$4 | D15: =POWER(C15,2)
B16: 0.5856 | C16: =B16-$G$4 | D16: =POWER(C16,2) | F16: Dado que el valor de la varianza: V(r) = 0,0867 está entre los límites de aceptación, podemos decir que no se puede rechazar que el conjunto de 100 números ri tiene una varianza de 1/12=0,08333.
B17: 0.1773 | C17: =B17-$G$4 | D17: =POWER(C17,2)
B18: 0.4394 | C18: =B18-$G$4 | D18: =POWER(C18,2)
B19: 0.3936 | C19: =B19-$G$4 | D19: =POWER(C19,2) | I19: 0.0618 | J19: ≤ | K19: 0.0867 | L19: ≤ | M19: 0.1081
B20: 0.9552 | C20: =B20-$G$4 | D20: =POWER(C20,2)
B21: 0.8548 | C21: =B21-$G$4 | D21: =POWER(C21,2)
B22: 0.5095 | C22: =B22-$G$4 | D22: =POWER(C22,2)
B23: 0.1257 | C23: =B23-$G$4 | D23: =POWER(C23,2)
B24: 0.6922 | C24: =B24-$G$4 | D24: =POWER(C24,2)
B25: 0.8527 | C25: =B25-$G$4 | D25: =POWER(C25,2)
B26: 0.3977 | C26: =B26-$G$4 | D26: =POWER(C26,2)
B27: 0.1735 | C27: =B27-$G$4 | D27: =POWER(C27,2)
B28: 0.2371 | C28: =B28-$G$4 | D28: =POWER(C28,2)
B29: 0.6232 | C29: =B29-$G$4 | D29: =POWER(C29,2)
B30: 0.1791 | C30: =B30-$G$4 | D30: =POWER(C30,2)
B31: 0.5352 | C31: =B31-$G$4 | D31: =POWER(C31,2)
... B102: 0.1397 | C102: =B102-$G$4 | D102: =POWER(C102,2)
B103: ='Generacion DD'!J111 | C103: =B103-$G$4 | D103: =POWER(C103,2)
B104: ='Generacion DD'!J112 | C104: =B104-$G$4 | D104: =POWER(C104,2)
B105: ='Generacion DD'!J113 | C105: =B105-$G$4 | D105: =POWER(C105,2)
B106: ='Generacion DD'!J114 | C106: =B106-$G$4 | D106: =POWER(C106,2)
B107: ='Generacion DD'!J115 | C107: =B107-$G$4 | D107: =POWER(C107,2)
B108: ='Generacion DD'!J116 | C108: =B108-$G$4 | D108: =POWER(C108,2)
B109: ='Generacion DD'!J117 | C109: =B109-$G$4 | D109: =POWER(C109,2)
B110: ='Generacion DD'!J118 | C110: =B110-$G$4 | D110: =POWER(C110,2)
...

Sheet Prueba Chi-Cuadrada
A1: Prueba Chi-Cuadrada
B4: 0.7864
B5: 0.8679 | F5: n = | G5: =COUNT(B4:B10003)
B6: 0.2069 | E6: intervalor | F6: m = | G6: =SQRT(G5) | H6: =ROUNDUP(G6,0)
B7: 0.0153 | E7: frecuencia esperada | F7: Ei = | G7: =G5/H6
B8: 0.8145 | I8: frecuencia observada | J8: frecuencia esperada
B9: 0.3639 | G9: Intervalo | I9: Oi | J9: Ei | K9: (Ei - Oi)2/Ei
B10: 0.374 | G10: 0 | H10: =G11-0.0001 | I10: =COUNTIFS($B$4:$B$10003,">=" &G10, $B$4:$B$10003, "<=" &H10) | J10: =$G$7 | K10: =(POWER(J10-I10,2))/J10
B11: 0.9117 | G11: 0.1 | H11: =G12-0.0001 | I11: =COUNTIFS($B$4:$B$10003,">=" &G11, $B$4:$B$10003, "<=" &H11) | J11: =$G$7 | K11: =(POWER(J11-I11,2))/J11
B12: 0.5389 | G12: 0.2 | H12: =G13-0.0001 | I12: =COUNTIFS($B$4:$B$10003,">=" &G12, $B$4:$B$10003, "<=" &H12) | J12: =$G$7 | K12: =(POWER(J12-I12,2))/J12
B13: 0.691 | G13: 0.3 | H13: =G14-0.0001 | I13: =COUNTIFS($B$4:$B$10003,">=" &G13, $B$4:$B$10003, "<=" &H13) | J13: =$G$7 | K13: =(POWER(J13-I13,2))/J13
B14: 0.7888 | G14: 0.4 | H14: =G15-0.0001 | I14: =COUNTIFS($B$4:$B$10003,">=" &G14, $B$4:$B$10003, "<=" &H14) | J14: =$G$7 | K14: =(POWER(J14-I14,2))/J14
B15: 0.9957 | G15: 0.5 | H15: =G16-0.0001 | I15: =COUNTIFS($B$4:$B$10003,">=" &G15, $B$4:$B$10003, "<=" &H15) | J15: =$G$7 | K15: =(POWER(J15-I15,2))/J15
B16: 0.011 | G16: 0.6 | H16: =G17-0.0001 | I16: =COUNTIFS($B$4:$B$10003,">=" &G16, $B$4:$B$10003, "<=" &H16) | J16: =$G$7 | K16: =(POWER(J16-I16,2))/J16
B17: 0.5856 | G17: 0.7 | H17: =G18-0.0001 | I17: =COUNTIFS($B$4:$B$10003,">=" &G17, $B$4:$B$10003, "<=" &H17) | J17: =$G$7 | K17: =(POWER(J17-I17,2))/J17
B18: 0.1773 | G18: 0.8 | H18: =G19-0.0001 | I18: =COUNTIFS($B$4:$B$10003,">=" &G18, $B$4:$B$10003, "<=" &H18) | J18: =$G$7 | K18: =(POWER(J18-I18,2))/J18
B19: 0.4394 | G19: 0.9 | H19: =G20-0.0001 | I19: =COUNTIFS($B$4:$B$10003,">=" &G19, $B$4:$B$10003, "<=" &H19) | J19: =$G$7 | K19: =(POWER(J19-I19,2))/J19
B20: 0.3936 | G20: 1 | K20: =SUM(K10:K19) | L20: valor estadistico
B21: 0.9552
B22: 0.8548 | F22: a = | G22: 0.05 | H22: 0.05
B23: 0.5095 | E23: valor critico | F23: m-1 = | G23: =H6-1
B24: 0.1257 | F24: X2 (0,05;9) = | G24: =ROUND(H24,3) | H24: =_xlfn.CHISQ.INV.RT(H22,G23) | J24: Busco en la Tabla X2 la Fila 3 y la Columna 0,01, y escribo el valor que se encuentra en la intersección de ambos valores.
B25: 0.6922
B26: 0.8527 | F26: Como el estadístico = 5,6000 es menor que el valor obtenido por tabla de 16,919 entonces no se puede rechazar que el conjunto de números ri sigue una distribución uniforme.
B27: 0.3977
B28: 0.1735
B29: 0.2371
B30: 0.6232
B31: 0.1791
B32: 0.5352
B33: 0.494
B34: 0.3005
B35: 0.9986
B36: 0.1654
B37: 0.8058
B38: 0.9007
... B103: 0.1397
B104: ='Generacion DD'!J111
B105: ='Generacion DD'!J112
B106: ='Generacion DD'!J113
...

Sheet Pruebas Corridas AyA
A1: Prueba de Corridas arriba y abajo
B3: 0.7864 | D3: S = {
B4: 0.8679 | D4: =IF(B4<=B3,0,1) | E4: 1 | F4: =SUM(E4:E10002)
B5: 0.2069 | D5: =IF(B5<=B4,0,1) | E5: 1
B6: 0.0153 | D6: =IF(B6<=B5,0,1)
B7: 0.8145 | D7: =IF(B7<=B6,0,1) | E7: 1
B8: 0.3639 | D8: =IF(B8<=B7,0,1) | E8: 1 | K8: a = | L8: 0.05 | M8: 0.05 | N8: ='Prueba de Medias'!$T$4 | O8: ='Prueba de Medias'!$U$4
B9: 0.374 | D9: =IF(B9<=B8,0,1) | E9: 1 | K9: a/2 = | L9: =M8/2
B10: 0.9117 | D10: =IF(B10<=B9,0,1) | G10: n = | H10: =COUNT(B3:B10002) | K10: 1-(a/2) = | L10: =1-L9 | M10: Ésto busco en el cuerpo de la tabla de distribución Normal estándar.
B11: 0.5389 | D11: =IF(B11<=B10,0,1) | E11: 1 | G11: m C0 = | H11: =((2*$H$10)-1)/3
B12: 0.691 | D12: =IF(B12<=B11,0,1) | E12: 1 | G12: σ²co = | H12: =((16*$H$10)-29)/90 | K12: nivel de aceptación = 95%
B13: 0.7888 | D13: =IF(B13<=B12,0,1) | G13: Z0 = | H13: =ABS(($F$4-$H$11)/(SQRT($H$12))) | K13: Z a/2 = | L13: El valor que escribo se forma sumando el valor de la fila más el valor de la Columna
B14: 0.9957 | D14: =IF(B14<=B13,0,1) | G14: Z a/2 = | H14: =NORMSINV(L10)
B15: 0.011 | D15: =IF(B15<=B14,0,1) | E15: 1
B16: 0.5856 | D16: =IF(B16<=B15,0,1) | E16: 1 | G16: Como el valor Z0 = 0,08 es menor que el valor crítico Z a/2 =1,96 de la tabla de Distribución Normal Estándar, se concluye que no se puede rechazar que los números del conjunto ri son independientes. Concluyendo con esta prueba que el conjunto de números ri se puede usar en un estudio de simulación.
B17: 0.1773 | D17: =IF(B17<=B16,0,1) | E17: 1
B18: 0.4394 | D18: =IF(B18<=B17,0,1) | E18: 1
B19: 0.3936 | D19: =IF(B19<=B18,0,1) | E19: 1
B20: 0.9552 | D20: =IF(B20<=B19,0,1) | E20: 1
B21: 0.8548 | D21: =IF(B21<=B20,0,1) | E21: 1
B22: 0.5095 | D22: =IF(B22<=B21,0,1)
B23: 0.1257 | D23: =IF(B23<=B22,0,1)
B24: 0.6922 | D24: =IF(B24<=B23,0,1) | E24: 1
B25: 0.8527 | D25: =IF(B25<=B24,0,1)
B26: 0.3977 | D26: =IF(B26<=B25,0,1) | E26: 1
B27: 0.1735 | D27: =IF(B27<=B26,0,1)
B28: 0.2371 | D28: =IF(B28<=B27,0,1) | E28: 1
B29: 0.6232 | D29: =IF(B29<=B28,0,1)
B30: 0.1791 | D30: =IF(B30<=B29,0,1) | E30: 1
B31: 0.5352 | D31: =IF(B31<=B30,0,1) | E31: 1
B32: 0.494 | D32: =IF(B32<=B31,0,1) | E32: 1
B33: 0.3005 | D33: =IF(B33<=B32,0,1)
B34: 0.9986 | D34: =IF(B34<=B33,0,1) | E34: 1
B35: 0.1654 | D35: =IF(B35<=B34,0,1) | E35: 1
B36: 0.8058 | D36: =IF(B36<=B35,0,1) | E36: 1
B37: 0.9007 | D37: =IF(B37<=B36,0,1)
B38: 0.9532 | D38: =IF(B38<=B37,0,1)
B39: 0.7483 | D39: =IF(B39<=B38,0,1) | E39: 1
B40: 0.8394 | D40: =IF(B40<=B39,0,1) | E40: 1
B41: 0.6896 | D41: =IF(B41<=B40,0,1) | E41: 1
...
